Workbook
Name FromArray_1: _xlfn.ANCHORARRAY(db!$B$2)

Sheet Restaurantesssssssssssssss
B2: 913699996 | H2: 218868209 | N2: 213428314 | T2: 961717778 | Z2: Restaurantes Olivier (Guilty, KOB, Yakuza, XXL)
B3: Trovas Antigas (5€) | H3: Parreirinha de Alfama (5€) | N3: A SEVERA (5€) | T3: Fado In Chiado (3€) | AF3: Hard Rock Café
B4: FADO | H4: FADO | N4: FADO | T4: FADO | Z4: Data | AA4: Hóspede | AB4: Quarto | AC4: Hora | AD4: Pax | AF4: FAST FOOD AMERICANA
B5: Data | C5: Hóspede | D5: Quarto | E5: Hora | F5: Pax | H5: Data | I5: Hóspede | J5: Quarto | K5: Hora | L5: Pax | N5: Data | O5: Hóspede | P5: Quarto | Q5: Hora | R5: Pax | T5: Data | U5: Hóspede | V5: Quarto | W5: Hora | X5: Pax | AF5: Data | AG5: Hóspede | AH5: Quarto | AI5: Hora | AJ5: Pax
B6: 45365 | C6: Marion Hebestreit | D6: 307 | E6: 19h00 | F6: 2 | H6: 45113 | I6: Liat Miller | K6: 20h00 | L6: 5
H7: 45156 | I7: Daniela Oliveira | K7: 20h30 | L7: 4
B23: Total: | E23: =+SUM(F6:F22)*5 -> 10 | H23: Total: | L23: =+SUM(L6:L22)*5 -> 45 | N23: Total: | Q23: =+SUM(R6:R22)*5 -> 0 | T23: Total: | W23: =+SUM(X6:X22)*3 -> 0 | Z23: Total: | AC23: =+SUM(AD6:AD21)*4 -> 0 | AF23: Total: | AI23: =+SUM(AJ7:AJ21)*4 -> 0
B25: Condições Trovas Antigas: | H25: Condições Parreirinha: | N25: Condições A Severa: | T25: Condições Fado In Chiado: | Z25: Condições Restaurantes Olivier: | AF25: Condições Hard Rock:
B26: Entregar Voucher aos hóspedes | H26: Pagamento em dinheiro | N26: Consumo mínimo de 45€ pax | T26: Entregas de comissão mensalmente- Ligar se não entregar até dia 05 | Z26: 4€ pax - Guilty (Pizzas, Pastas, Hamburgers, etc); KOB (Carnes Maturadas); Yakuza (Sushi) | AF26: 1€ pax até 20 pessoas | 2€ pax de 21 a 30 pessoas | 3€ pax de 31 a 60 pessoas | 4€ pax mais de 60 pessoas
B27: Pagamento efetuado no restaurante | H27: 55€ pax: menu + espetáculo - bebidas à parte | N27: Entregas de comissão mensalmente- Ligar se não entregar até dia 10
B28: 45€ pax: 1 prato principal + 1 sobremesa + 1 bebida + espetáculo | H28: Entrega comissões mensalmente (temos de marcar com regularidade) | Z28: 5€ pax - XXL (Comida típica Portuguesa)
H31: 213460088 | N31: 213421305 | T31: 210523906 | Z31: 911777388 | AF31: 213460501
B32: 213420572 | H32: Carmo Restaurant & Bar (2€) | N32: Mar ao Carmo (2€) | T32: Mar ao Largo (2€) | Z32: Lisboa em Fado (4€) | AF32: Café in Chiado (4€)
B33: Sacramento do Chiado (3€) | H33: TRADICIONAL PORTUGUESA | N33: MARISQUEIRA | T33: MARISQUEIRA + TRADICIONAL | Z33: FADO | AF33: Comida tipica portuguesa
B34: TRADICIONAL PORTUGUESA | H34: Data | I34: Hóspede | J34: Quarto | K34: Hora | L34: Pax | N34: Data | O34: Hóspede | P34: Quarto | Q34: Hora | R34: Pax | T34: Data | U34: Hóspede | V34: Quarto | W34: Hora | X34: Pax | Z34: Data | AA34: Hóspede | AB34: Quarto | AC34: Hora | AD34: Pax | AF34: Data | AG34: Hóspede | AH34: Quarto | AI34: Hora | AJ34: Pax
B35: Data | C35: Hóspede | D35: Quarto | E35: Hora | F35: Pax | T35: 45331 | U35: Enrique Carlos | W35: 12h00 | X35: 14 | Z35: 45356 | AA35: Tsvika Nir | AB35: 203 + 303 | AC35: 18h | AD35: 4
B36: 45353 | C36: STOJANOVIC | D36: 315 | E36: 21h | F36: 7
H52: Total: | L52: =+SUM(L35:L50)*2 -> 0 | N52: Total: | R52: =+SUM(R35:R50)*2 -> 0 | T52: Total: | X52: =+SUM(X35:X50)*2 -> 28 | Z52: Total: | AC52: =+SUM(AD35:AD50)*4 -> 16
B53: Total: | F53: =+SUM(F36:F51)*3 -> 21 | AF53: Total: | AI53: =+SUM(AJ35:AJ51)*4 -> 0
Z54: Condições Lisboa em Fado:
B55: Condições de pagamento Sacramento do Chiado; Mar ao Carmo; Carmo; Mar ao largo | Z55: Temos de ir lá todos os meses para recebermos as comissões | AF55: Condições Hard Rock:
B56: Enviar email no final do mês com todas reservas destes restaurantes para inesdamasceno@tablegroup.pt e marcar um dia para ela nos dar as comissões. | AF56: Mandar clientes com voucher
O58: 963342983
B59: Seisan | I59: Figus | O59: Monte Mar (5€)
B60: Japonês | I60: TRADICIONAL PORTUGUESA | O60: Marisqueira
B61: Data | C61: Hóspede | D61: Quarto | E61: Hora | F61: Pax | I61: Data | J61: Hóspede | K61: Quarto | L61: Hora | M61: Pax | O61: Data | P61: Hóspede | Q61: Quarto | R61: Hora | S61: Pax
B62: 45291 | C62: Olivier Marie | E62: 20h00 | F62: 2 | I62: 45291 | J62: Lars-anders Callenberg | L62: 19h00 | M62: 2
B79: Total: | I79: Total: | O79: Total:
O80: Condições Monte Mar:
O81: Entregam mensalmente, Por cada 40 pessoas oferecem um voucher para o hotel

Sheet Transfers Janeiro
B1: MSH ROSSIO - TRANSFERS JANEIRO 2023
C2: * Por favor conferir comissões de transfers pagos ao hotel e modificar cor para
B3: SUNDESTINY | F3: Rita & Pedro Lobo | G3: 962930401 | H3: 962522529 | M3: 7 Roads | Q3: Carla | R3: 939660691
B5: Data | C5: Horas | D5: Cliente | E5: Quarto | F5: Serviço | G5: Empresa | H5: Valor | I5: Comissão | J5: Nº pax | M5: Data | N5: Horas | O5: Cliente | P5: Quarto | Q5: Serviço | R5: Empresa | S5: Valor | T5: Comissão | U5: Nº pax
B6: 44562 | C6: 06h15 | D6: Edward Gaballa | F6: Aeroporto-Hotel | G6: SunDestiny | H6: 70 | I6: 6.25 | J6: 2 | K6: AR | M6: 44930 | N6: 14h35 | O6: Lisa Parks | Q6: Aeroporto-Hotel | R6: 7 Roads | S6: 39 | U6: 2
B7: 44562 | C7: 08h10 | D7: Alexandra Kelly | F7: Aeroporto-Hotel | G7: SunDestiny | H7: 70 | I7: 6.25 | J7: 2 | K7: CB | M7: 44935 | N7: 06h00 | O7: Mark Snoozy | Q7: Aeroporto-Hotel | R7: 7 Roads | S7: 39 | U7: 2
B8: 44562 | C8: 15h25 | D8: Debbie Fernandes | F8: Aeroporto-Hotel | G8: SunDestiny | H8: 140 | I8: 20 | J8: 8 | K8: AR | M8: 44941 | N8: 07h00 | O8: Erinn Meehan | Q8: Hotel-Aeroporto | R8: 7 Roads | S8: 22 | U8: 2
B9: 44928 | C9: 12h00 | D9: Muriel Quaderno | E9: 201 + 207 | F9: Hotel-Aeroporto | G9: SunDestiny | H9: 30 | I9: 7.5 | J9: 4 | K9: AR | M9: 44942 | N9: 11h40 | O9: Djenne Grant | Q9: Aeroporto-Hotel | R9: 7 Roads | S9: 39 | U9: 2
B10: 44928 | C10: 08h30 | D10: Debbie Fernandes | E10: 404 | F10: Hotel-Aeroporto | G10: SunDestiny | H10: 50 | I10: 10 | J10: 8 | K10: CB | M10: 44951 | N10: 22h20 | O10: Eric Lecat | Q10: Aeroporto-Hotel | R10: 7 Roads | S10: 39 | U10: 2
B11: 44928 | C11: 17h15 | D11: Samuel Anacito | F11: Aeroporto-Hotel | G11: SunDestiny | H11: 35 | I11: 5 | J11: 2 | K11: AR | M11: 44954 | N11: 15h00 | O11: Eric Lecat | Q11: Hotel-Aeroporto | R11: 7 Roads | S11: 22 | U11: 2
B12: 44564 | C12: 12h30 | D12: Taylor Wallace | F12: Aeroporto-Hotel | G12: SunDestiny | H12: 35 | I12: 5 | J12: 2 | K12: DO
B13: 44931 | C13: 19h50 | D13: Dominik Honegger | F13: Aeroporto-Hotel | G13: SunDestiny | H13: 35 | I13: 5 | J13: 2 | K13: AR
B14: 44932 | C14: 05h30 | D14: Rainer Fronlick | E14: 210 | F14: Hotel-Aeroporto | G14: SunDestiny | H14: 25 | I14: 7 | J14: 2 | K14: DO
B15: 44932 | C15: 06h20 | D15: Gebauer | E15: 204 + 216 | F15: Hotel-Aeroporto | G15: SunDestiny | H15: 30 | I15: 7.5 | J15: 3 | K15: AS
B16: 44934 | C16: 17h00 | D16: Dominik Honegger | E16: 401 | F16: Hotel-Aeroporto | G16: SunDestiny | H16: 25 | I16: 7 | J16: 2 | K16: AR
B17: 44571 | C17: 12h45 | D17: James Perone | F17: Aeroporto-Hotel | G17: SunDestiny | H17: 35 | I17: 5 | J17: 1 | K17: CB
B18: 44937 | C18: 15h20 | D18: Terje Nepper | F18: Aeroporto-Hotel | G18: SunDestiny | H18: 35 | I18: 5 | J18: 2 | K18: AG
B19: 44572 | C19: 15h35 | D19: Sarah Robertson | F19: Aeroporto-Hotel | G19: SunDestiny | H19: 35 | I19: 5 | J19: 1 | K19: AG
B20: 44937 | C20: 07h30 | D20: James Perone | E20: 308 | F20: Hotel-Aeroporto | G20: SunDestiny | H20: 25 | I20: 7 | J20: 1 | K20: SD
B21: 44937 | C21: 09h40 | D21: Shmuel Roizman | F21: Aeroporto-Hotel | G21: SunDestiny | H21: 35 | I21: 5 | J21: 2 | K21: AR
B22: 44938 | C22: 02h30 | D22: Marcia Machado | E22: 311 + 211 | F22: Hotel-Aeroporto | G22: SunDestiny | H22: 40 | I22: 10 | J22: 5 | K22: AS
B23: 44573 | C23: 05h15 | D23: Fanny Wong Lam | F23: Hotel-Aeroporto | G23: SunDestiny | H23: 30 | I23: 7.5 | J23: 3 | K23: AS
B24: 44938 | C24: 12h30 | D24: Nilson Filho | F24: Aeroporto-Hotel | G24: SunDestiny | H24: 35 | I24: 5 | J24: 2 | K24: FP
B25: 44574 | C25: 17h15 | D25: Stephanie Ripzaad | F25: Aeroporto-Hotel | G25: SunDestiny | H25: 35 | I25: 5 | J25: 2 | K25: AR
B26: 44939 | C26: 09h50 | D26: Michael Shepherd | F26: Aeroporto-Hotel | G26: SunDestiny | H26: 35 | I26: 5 | J26: 2 | K26: AR
B27: 44940 | C27: 08h30 | D27: Sarah Robertson | E27: 408 | F27: Hotel-Aeroporto | G27: SunDestiny | H27: 25 | I27: 7 | J27: 1 | K27: AS
B28: 44940 | C28: 13H55 | D28: Nepper, Terje | E28: 415 | F28: Hotel-Aeroporto | G28: SunDestiny | H28: 25 | I28: 7 | J28: 2 | K28: AS
B29: 44940 | C29: 11h30 | D29: Shmuel Roizman | E29: 204 | F29: Hotel-Aeroporto | G29: SunDestiny | H29: 25 | I29: 7 | J29: 2 | K29: CB
B30: 44941 | C30: 04h00 | D30: Jose Alcantara | E30: 201 | F30: Hotel-Aeroporto | G30: SunDestiny | H30: 25 | I30: 7 | J30: 1 | K30: DO
B31: 44941 | C31: 13H00 | D31: Nilson Filho | E31: 304 | F31: Hotel-Aeroporto | G31: SunDestiny | H31: 25 | I31: 7 | J31: 2 | K31: CB
B32: 44576 | C32: 23h10 | D32: Susan Knowler | F32: Aeroporto-Hotel | G32: SunDestiny | H32: 35 | I32: 5 | J32: 2 | K32: AR
B33: 44942 | C33: 05h30 | D33: Maria Gomez | E33: 315 | F33: Aeroporto-Hotel | G33: SunDestiny | H33: 35 | I33: 5 | J33: 2 | K33: AR
B34: 44943 | C34: 05h00 | D34: Maria Gomez | E34: 315 | F34: Hotel-Aeroporto | G34: SunDestiny | H34: 25 | I34: 7 | J34: 2 | K34: DO
B35: 44943 | C35: 07h15 | D35: Magaly Bouteraon | E35: 406 | F35: Hotel-Aeroporto | G35: SunDestiny | H35: 25 | I35: 7 | J35: 2 | K35: DO
B36: 44943 | C36: 09h20 | D36: Marcelo Yeh | F36: Aeroporto-Hotel | G36: SunDestiny | H36: 70 | I36: 15 | J36: 4 | K36: AR
B37: 44578 | C37: 12h40 | D37: Afreen Alam | F37: Aeroporto-Hotel | G37: SunDestiny | H37: 35 | I37: 5 | J37: 2 | K37: AS
B38: 44579 | C38: 07h00 | D38: Afreen Alam | F38: Hotel-Aeroporto | G38: SunDestiny | H38: 25 | I38: 7 | J38: 2 | K38: AS
B39: 44945 | C39: 13h10 | D39: Mrs Hinley | F39: Aeroporto-Hotel | G39: SunDestiny | H39: 35 | I39: 5 | J39: 2 | K39: AR
B40: 44946 | C40: 19h30 | D40: Jasmin klink | F40: Aeroporto-Hotel | G40: SunDestiny | H40: 35 | I40: 5 | J40: 2 | K40: AG
B41: 44948 | C41: 10H00 | D41: Jasmin klink | F41: Hotel-Aeroporto | G41: SunDestiny | H41: 25 | I41: 7 | J41: 2 | K41: CB
...

Sheet Transfers Fevereiro
B1: MSH ROSSIO - TRANSFERS FEVEREIRO 2023
C2: * Por favor conferir comissões de transfers pagos ao hotel e modificar cor para
B3: SUNDESTINY | F3: Rita & Pedro Lobo | G3: 962930401 | H3: 962522529 | M3: 7 Roads | Q3: Carla | R3: 939660691
B5: Data | C5: Horas | D5: Cliente | E5: Quarto | F5: Serviço | G5: Empresa | H5: Valor | I5: Comissão | J5: Nº pax | M5: Data | N5: Horas | O5: Cliente | P5: Quarto | Q5: Serviço | R5: Empresa | S5: Valor | T5: Comissao | U5: Nº pax
B6: 44960 | C6: 14h55 | D6: Kevin Cassidy | F6: Aeroporto-Hotel | G6: SunDestiny | H6: 35 | I6: 5 | J6: 2 | K6: FP | M6: 44959 | N6: 17h50 | O6: Gina Gentry | Q6: Aeroporto-Hotel | R6: 7 Roads | S6: 39 | U6: 2
B7: 44961 | C7: 15h10 | D7: Ingo Eppmann | F7: Aeroporto-Hotel | G7: SunDestiny | H7: 35 | I7: 5 | J7: 2 | K7: CB | M7: 44961 | N7: 10h30 | O7: Donna Perfine | Q7: Aeroporto-Hotel | R7: 7 Roads | S7: 39 | U7: 2
B8: 44961 | C8: 05h00 | D8: Elkær-hansen | E8: 207 | F8: Hotel-Aeroporto | G8: SunDestiny | H8: 25 | I8: 7 | J8: 2 | K8: DO | M8: 44981 | N8: 22h25 | O8: Virginie Sauquillo | Q8: Aeroporto-Hotel | R8: 7 Roads | S8: 39 | U8: 2
B9: 44962 | C9: 14h35 | D9: Steve Ross | F9: Aeroporto-Hotel | G9: SunDestiny | H9: 35 | I9: 5 | J9: 2 | K9: AR | M9: 44984 | N9: 02h30 | O9: James Roberts | Q9: Hotel-Aeroporto | R9: 7 Roads | S9: 22 | U9: 2
B10: 44963 | C10: 08h00 | D10: Heather Raposa | E10: 303 | F10: Hotel-Aeroporto | G10: SunDestiny | H10: 25 | I10: 7 | J10: 2 | K10: AR | M10: 44985 | N10: 18h45 | O10: Pascal Lefebvre | Q10: Aeroporto-Hotel | R10: 7 Roads | S10: 39 | U10: 2
B11: 44963 | C11: 09h40 | D11: Tzvi Bar Heim | F11: Aeroporto-Hotel | G11: SunDestiny | H11: 35 | I11: 5 | J11: 2 | K11: AR
B12: 44964 | C12: 14h35 | D12: Deborah Hemmeter | F12: Aeroporto-Hotel | G12: SunDestiny | H12: 35 | I12: 5 | J12: 2 | K12: AR
B13: 44964 | C13: 17h20 | D13: Marco Pergola | F13: Aeroporto-Hotel | G13: SunDestiny | H13: 35 | I13: 5 | J13: 2 | K13: AS
B14: 44965 | C14: 14h10 | D14: Isabella Valletta | F14: Aeroporto-Hotel | G14: SunDestiny | H14: 35 | I14: 5 | J14: 2 | K14: AR
B15: 44967 | C15: 07h30 | D15: Mary Burke | E15: 305+307 | F15: Hotel-Aeroporto | G15: SunDestiny | H15: 40 | I15: 10 | J15: 4 | K15: CB
B16: 44602 | C16: 14h10 | D16: Niccolò Narni | F16: Aeroporto-Hotel | G16: SunDestiny | H16: 35 | I16: 5 | J16: 2 | K16: Bárbara
B17: 44968 | C17: 08h45 | D17: Elisa Milani | F17: Aeroporto-Hotel | G17: SunDestiny | H17: 35 | I17: 5 | J17: 2 | K17: DO
B18: 44968 | C18: 12h35 | D18: Juan Cengotitabengoa | F18: Aeroporto-Hotel | G18: SunDestiny | H18: 35 | I18: 5 | J18: 2 | K18: AS
B19: 44968 | C19: 06h00 | D19: Philomena Mary Dooley | E19: 407 | F19: Hotel-Aeroporto | G19: SunDestiny | H19: 25 | I19: 7 | J19: 2 | K19: CB
B20: 44969 | C20: 11h20 | D20: Sophia Ciurleo | F20: Aeroporto-Hotel | G20: SunDestiny | H20: 35 | I20: 5 | J20: 2 | K20: FP
B21: 44970 | C21: 08h55 | D21: Pascale Charland | F21: Aeroporto-Hotel | G21: SunDestiny | H21: 35 | I21: 5 | J21: 1 | K21: AR
B22: 44972 | C22: 23h10 | D22: Keisuke Kuroda | F22: Aeroporto-Hotel | G22: SunDestiny | H22: 35 | I22: 5 | J22: 1 | K22: AG
B23: 44972 | C23: 15h10 | D23: Clayton Liston Halliday | F23: Aeroporto-Hotel | G23: SunDestiny | H23: 35 | I23: 5.001 | J23: 1 | K23: AR
B24: 44972 | C24: 07h00 | D24: Jill Praisner | F24: Hotel-Aeroporto | G24: SunDestiny | H24: 25 | I24: 7 | J24: 2 | K24: AR
B25: 44973 | C25: 06h30 | D25: Sevil Kutay | E25: 304 | F25: Hotel-Aeroporto | G25: SunDestiny | H25: 25 | I25: 7 | J25: 2 | K25: DO
B26: 44973 | C26: 06h30 | D26: Claire Haselint | E26: 402 | F26: Hotel-Aeroporto | G26: SunDestiny | H26: 25 | I26: 7 | J26: 2 | K26: DO
B27: 44973 | C27: 10h35 | D27: Hannah Press | F27: Aeroporto-Hotel | G27: SunDestiny | H27: 35 | I27: 5 | J27: 2 | K27: AS
B28: 44973 | C28: 12h55 | D28: Cornelia Ziegler | F28: Aeroporto-Hotel | G28: SunDestiny | H28: 35 | I28: 5 | J28: 2 | K28: AR
B29: 44973 | C29: 15h50 | D29: OLATI GIORGIO | F29: Aeroporto-Hotel | G29: SunDestiny | H29: 80 | I29: 15 | J29: 8 | K29: CB
B30: 44974 | C30: 02h00 | D30: William Hodges | E30: 303 | F30: Hotel-Aeroporto | G30: SunDestiny | H30: 25 | I30: 7 | J30: 3 | K30: CB
B31: 44974 | C31: 04h30 | D31: Keisuke Kuroda | E31: 310 | F31: Hotel-Aeroporto | G31: SunDestiny | H31: 25 | I31: 7 | J31: 1 | K31: AG
B32: 44974 | C32: 05h25 | D32: Bruce Stanforth | E32: 206 | F32: Aeroporto-Hotel | G32: SunDestiny | H32: 35 | I32: 5 | J32: 2 | K32: AR
B33: 44974 | C33: 06h15 | D33: Edward Smith | E33: 204 | F33: Hotel-Aeroporto | G33: SunDestiny | H33: 25 | I33: 7 | J33: 2 | K33: DO
B34: 44974 | C34: 12h00 | D34: John Spataro | E34: 204 | F34: Aeroporto-Hotel | G34: SunDestiny | H34: 35 | I34: 5 | J34: 2 | K34: FP
B35: 44974 | C35: 13h00 | D35: Lidia Santos | E35: 102 | F35: Hotel-Aeroporto | G35: SunDestiny | H35: 25 | I35: 7 | J35: 2 | K35: DO
B36: 44975 | C36: 08h15 | D36: Michael Chapiro | E36: 302 | F36: Hotel-Aeroporto | G36: SunDestiny | H36: 25 | I36: 7 | J36: 2 | K36: DO
B37: 44975 | C37: 16h50 | D37: Patricia Bernard | F37: Aeroporto-Hotel | G37: SunDestiny | H37: 35 | I37: 5 | J37: 3 | K37: AS
B38: 44976 | C38: 05h00 | D38: Aurelie Marie | E38: 311 | F38: Hotel-Aeroporto | G38: SunDestiny | H38: 25 | I38: 7 | J38: 2 | K38: AG
B39: 44976 | C39: 04h15 | D39: Beth Brennan | E39: 101 | F39: Hotel-Aeroporto | G39: SunDestiny | H39: 25 | I39: 7 | J39: 2 | K39: DO
B40: 44976 | C40: 11h50 | D40: Marco Meichtry | F40: Aeroporto-Hotel | G40: SunDestiny | H40: 35 | I40: 5 | J40: 2 | K40: DO
B41: 44977 | C41: 04h40 | D41: Karen | E41: 215 | F41: Hotel-Aeroporto | G41: SunDestiny | H41: 25 | I41: 7 | J41: 2 | K41: AS
...

Sheet Transfers Março
B1: MSH ROSSIO - TRANSFERS MARÇO 2023
C2: * Por favor conferir comissões de transfers pagos ao hotel e modificar cor para
B3: SUNDESTINY | F3: Rita & Pedro Lobo | G3: 962930401 | H3: 962522529 | M3: 7 Roads | Q3: Carla | R3: 939660691
B5: Data | C5: Horas | D5: Cliente | E5: Quarto | F5: Serviço | G5: Empresa | H5: Valor | I5: Comissão | J5: Nº pax | M5: Data | N5: Horas | O5: Cliente | P5: Quarto | Q5: Serviço | R5: Empresa | S5: Valor | T5: Nº pax
B6: 44986 | C6: 06h30 | D6: Olga Kaye | E6: 403 | F6: Hotel-Aeroporto | G6: SunDestiny | H6: 25 | I6: 7 | J6: 2 | K6: CB | M6: 44993 | N6: 10h20 | O6: Robert Chadwick | Q6: Aeroporto-Hotel | R6: 7 Roads | S6: 39 | T6: 2
B7: 44986 | C7: 08h25 | D7: Thomas Briola | F7: Aeroporto-Hotel | G7: SunDestiny | H7: 35 | I7: 5 | J7: 2 | K7: DO | M7: 44992 | N7: 12h30 | O7: Julia | P7: 411 | Q7: Hotel-Aeroporto | R7: 7 Roads | S7: 22 | T7: 2
B8: 44986 | C8: 10h30 | D8: James Rayner | F8: Aeroporto-Hotel | G8: SunDestiny | H8: 35 | I8: 5 | J8: 2 | K8: AR | M8: 44995 | N8: 09h00 | O8: Gregory Crosland | Q8: Aeroporto-Hotel | R8: 7 Roads | S8: 39 | T8: 2
B9: 44987 | C9: 07h45 | D9: Michael Scrimes | E9: 401 | F9: Hotel-Aeroporto | G9: SunDestiny | H9: 25 | I9: 7 | J9: 2 | K9: DO | M9: 44995 | N9: 08h35 | O9: Robert Chadwick | P9: 401 | Q9: Hotel-Aeroporto | R9: 7 Roads | S9: 22 | T9: 2
B10: 44987 | C10: 17h50 | D10: Dganit Chen Shapira | F10: Aeroporto-Hotel | G10: SunDestiny | H10: 50 | I10: 10 | J10: 4 | K10: AR | M10: 44998 | N10: 21h05 | O10: David Robertson | Q10: Aeroporto-Hotel | R10: 7 Roads | S10: 39 | T10: 2
B11: 44987 | C11: 19h50 | D11: Laura Whittle | F11: Aeroporto-Hotel | G11: SunDestiny | H11: 35 | I11: 5 | J11: 2 | K11: AR | M11: 45004 | N11: 17h50 | O11: Elad Cohen | Q11: Aeroporto-Hotel | R11: 7 Roads | S11: 39 | T11: 1
B12: 44988 | C12: 14h35 | D12: Valérie Geffroy | F12: Aeroporto-Hotel | G12: SunDestiny | H12: 35 | I12: 5 | J12: 2 | K12: AR | M12: 45007 | N12: 08h50 | O12: Sylvia Galbraith | Q12: Aeroporto-Hotel | R12: 7 Roads | S12: 39 | T12: 2
B13: 44988 | C13: 17h15 | D13: Steffie Loots | F13: Aeroporto-Hotel | G13: SunDestiny | H13: 35 | I13: 5 | J13: 2 | K13: CB | M13: 45009 | N13: 12h30 | O13: Elad Cohen | P13: 408 | Q13: Hotel-Aeroporto | R13: 7 Roads | S13: 22 | T13: 1
B14: 44989 | C14: 05h00 | D14: Elena Loureiro | E14: 215 | F14: Hotel-Aeroporto | G14: SunDestiny | H14: 30 | I14: 7.5 | J14: 4 | K14: AR
B15: 44989 | C15: 16h15 | D15: Amy Woolridge | F15: Aeroporto-Hotel | G15: SunDestiny | H15: 35 | I15: 5 | J15: 2 | K15: AR
B16: 44989 | C16: 18h05 | D16: Kay Farinazzo | F16: Aeroporto-Hotel | G16: SunDestiny | H16: 35 | I16: 5 | J16: 2 | K16: DO
B17: 44990 | C17: 08h30 | D17: Sally Mandon | E17: 311 | F17: Hotel-Aeroporto | G17: SunDestiny | H17: 25 | I17: 7 | J17: 2 | K17: CB
B18: 44990 | C18: 17h15 | D18: Laura Whittle | E18: 216 | F18: Hotel-Aeroporto | G18: SunDestiny | H18: 25 | I18: 7 | J18: 2 | K18: AS
B19: 44991 | C19: 16h15 | D19: Dganit Chen Shapira | E19: 303 | F19: Hotel-Aeroporto | G19: SunDestiny | H19: 30 | I19: 7.5 | J19: 4 | K19: AR
B20: 44992 | C20: 19h45 | D20: Heike Kosching-Förste | F20: Aeroporto-Hotel | G20: SunDestiny | H20: 50 | I20: 10 | J20: 4 | K20: AR
B21: 44992 | C21: 07h15 | D21: Carol Anne Dedecker | E21: 409 | F21: Hotel-Aeroporto | G21: SunDestiny | H21: 25 | I21: 7 | J21: 2 | K21: AS
B22: 44992 | C22: 23h15 | D22: Alice Koral Zabari | F22: Aeroporto-Hotel | G22: SunDestiny | H22: 35 | I22: 5 | J22: 2 | K22: AS
B23: 44993 | C23: 05h00 | D23: Liliana | E23: 303 | F23: Hotel-Aeroporto | G23: SunDestiny | H23: 25 | I23: 7 | J23: 2 | K23: AS
B24: 44993 | C24: 12h00 | D24: Brian Boucher | F24: Aeroporto-Hotel | G24: SunDestiny | H24: 35 | I24: 5 | J24: 2 | K24: CB
B25: 44994 | C25: 08h00 | D25: Briola | E25: 415 | F25: Hotel-Aeroporto | G25: SunDestiny | H25: 25 | I25: 7 | J25: 2 | K25: RL
B26: 44994 | C26: 10h05 | D26: Jae Lim | F26: Aeroporto-Hotel | G26: SunDestiny | H26: 35 | I26: 5 | J26: 2 | K26: AS
B27: 44995 | C27: 02h00 | D27: Jeon, Seongmin | E27: 409 | F27: Hotel-Aeroporto | G27: SunDestiny | H27: 25 | I27: 7 | J27: 2 | K27: BM
B28: 44995 | C28: 08h00 | D28: Rachel Selvin | F28: Aeroporto-Hotel | G28: SunDestiny | H28: 35 | I28: 5 | J28: 2 | K28: AR
B29: 44995 | C29: 09h30 | D29: Loriano Tomelleri | F29: Aeroporto-Hotel | G29: SunDestiny | H29: 35 | I29: 5 | J29: 2 | K29: AR
B30: 44996 | C30: 06h30 | D30: Nelson Costa | E30: 208 | F30: Hotel-Aeroporto | G30: SunDestiny | H30: 25 | I30: 7 | J30: 1 | K30: AR
B31: 44996 | C31: 08h30 | D31: Jafchul Lim | E31: 415 | F31: Hotel-Aeroporto | G31: SunDestiny | H31: 25 | I31: 7 | J31: 2 | K31: AR
B32: 44996 | C32: 09h00 | D32: Bruce Sharp | E32: 307+215 | F32: Hotel-Sete Rios | G32: SunDestiny | H32: 30 | I32: 7.5 | J32: 4 | K32: CB
B33: 44997 | C33: 08h50 | D33: Maureen Wallis-Borrelli | F33: Aeroporto-Hotel | G33: SunDestiny | H33: 35 | I33: 5.002 | J33: 2 | K33: AR
B34: 44997 | C34: 16h25 | D34: Jacob Borrelli | F34: Aeroporto-Hotel | G34: SunDestiny | H34: 35 | I34: 5 | J34: 1 | K34: AR
B35: 44998 | C35: 04h00 | D35: Julie Oliver | F35: Hotel-Aeroporto | G35: SunDestiny | H35: 25 | I35: 7 | J35: 2 | K35: AS
B36: 44998 | C36: 09h00 | D36: Jasmin Fuchs | F36: Aeroporto-Hotel | G36: SunDestiny | H36: 35 | I36: 5 | J36: 2 | K36: AR
B37: 44998 | C37: 10h45 | D37: Elina Bakhiieva | F37: Aeroporto-Hotel | G37: SunDestiny | H37: 35 | I37: 5 | J37: 1 | K37: AR
B38: 44998 | C38: 15h20 | D38: Chantale Giguère | F38: Aeroporto-Hotel | G38: SunDestiny | H38: 35 | I38: 5 | J38: 2 | K38: AS
B39: 44998 | C39: 18h55 | D39: Paula Smith | F39: Aeroporto-Hotel | G39: SunDestiny | H39: 35 | I39: 5 | J39: 2 | K39: AR
B40: 44998 | C40: 19h10 | D40: Esmé Wiertz | F40: Aeroporto-Hotel | G40: SunDestiny | H40: 35 | I40: 5 | J40: 2 | K40: CB
B41: 44999 | C41: 11h50 | D41: Kelly Yee | F41: Aeroporto-Hotel | G41: SunDestiny | H41: 35 | I41: 5 | J41: 2 | K41: DO
...

Sheet Transfers Abril
B1: MSH ROSSIO - TRANSFERS ABRIL 2023
C2: * Por favor conferir comissões de transfers pagos ao hotel e modificar cor para
B3: SUNDESTINY | F3: Rita & Pedro Lobo | G3: 962930401 | H3: 962522529 | M3: 7 Roads | Q3: Carla | R3: 939660691
B5: Data | C5: Horas | D5: Cliente | E5: Quarto | F5: Serviço | G5: Empresa | H5: Valor | I5: Comissão | J5: Nº pax | M5: Data | N5: Horas | O5: Cliente | P5: Quarto | Q5: Serviço | R5: Empresa | S5: Valor | T5: Nº pax
B6: 45017 | C6: 19h40 | D6: Michael Arnold | F6: Aeroporto-Hotel | G6: SunDestiny | H6: 35 | I6: 5 | J6: 2 | K6: CB | M6: 45018 | N6: 08h20 | O6: Brigid Grode | Q6: Aeroporto-Hotel | R6: 7 Roads | S6: 39 | T6: 2
B7: 45018 | C7: 08h20 | D7: Shimie Hortig | F7: Aeroporto-Hotel | G7: SunDestiny | H7: 35 | I7: 5 | J7: 3 | K7: AR | M7: 45020 | N7: 07h30 | O7: Kenneth Coffman | Q7: Hotel-Aeroporto | R7: 7 Roads | S7: 22 | T7: 2
B8: 45018 | C8: 09h10 | D8: Liat Hortig | F8: Aeroporto-Hotel | G8: SunDestiny | H8: 35 | I8: 5 | J8: 1 | K8: AR | M8: 45020 | N8: 10h00 | O8: Suzanne Thorniley | Q8: Hotel-Aeroporto | R8: 7 Roads | S8: 22 | T8: 1
B9: 45018 | C9: 10h30 | D9: Sascha Hellbeck | E9: 302 | F9: Hotel-Aeroporto | G9: SunDestiny | H9: 40 | I9: 10 | J9: 4 | K9: CB | M9: 45025 | N9: 08h00 | O9: Michael Holloway | Q9: Hotel-Aeroporto | R9: 7 Roads | S9: 22 | T9: 2
B10: 45018 | C10: 11h00 | D10: Rose Edmands | E10: 303 | F10: Hotel-Aeroporto | G10: SunDestiny | H10: 25 | I10: 7 | J10: 2 | K10: DO | M10: 45031 | N10: 06h30 | O10: Victor Wolff | P10: 202 | Q10: Hotel-Aeroporto | R10: 7 Roads | S10: 22 | T10: 2
B11: 45020 | C11: 09h30 | D11: Stephen Williams | E11: 207 | F11: Hotel-Aeroporto | G11: SunDestiny | H11: 25 | I11: 7 | J11: 2 | K11: AR | M11: 45036 | N11: 03h30 | O11: Sarah Whitmore | P11: 202 | Q11: Hotel-Aeroporto | R11: 7 Roads | S11: 22 | T11: 2
B12: 45020 | C12: 12h20 | D12: David Harrison | F12: Aeroporto-Hotel | G12: SunDestiny | H12: 35 | I12: 5 | J12: 2 | K12: DO | M12: 45037 | N12: 11h15 | O12: David Clay | Q12: Aeroporto-Hotel | R12: 7 Roads | S12: 39 | T12: 2
B13: 45020 | C13: 12h30 | D13: Gruver | F13: Hotel-Aeroporto | G13: SunDestiny | H13: 25 | I13: 7 | J13: 2 | K13: AR | M13: 45037 | N13: 09H05 | O13: John Terrio | Q13: Aeroporto-Hotel | R13: 7 Roads | S13: 39 | T13: 2
B14: 45021 | C14: 15h35 | D14: Diane Amer | F14: Aeroporto-Hotel | G14: SunDestiny | H14: 35 | I14: 5 | J14: 2 | K14: DO | M14: 45041 | N14: 09h45 | O14: Leigh Knight | Q14: Aeroporto-Hotel | R14: 7 Roads | S14: 39 | T14: 2
B15: 45021 | C15: 21h35 | D15: Claire Costello | F15: Aeroporto-Hotel | G15: SunDestiny | H15: 35 | I15: 5 | J15: 2 | K15: DO | M15: 45041 | N15: 15h15 | O15: Cheryl Laney | Q15: Aeroporto-Hotel | R15: 7 Roads | S15: 39 | T15: 2
B16: 45021 | C16: 15h30 | D16: Familia Meneses | F16: Hotel-Aeroporto | G16: SunDestiny | H16: 80 | I16: 20 | J16: 12 | K16: DO | M16: 45042 | N16: 07h00 | O16: Leigh Knight | P16: 415 | Q16: Hotel-Aeroporto | R16: 7 Roads | S16: 22 | T16: 2
B17: 45022 | C17: 06h30 | D17: Gerald Schneider | E17: 316 | F17: Hotel-Aeroporto | G17: SunDestiny | H17: 25 | I17: 7 | J17: 2 | K17: CB | M17: 45043 | N17: 11h10 | O17: Susan Thomson | Q17: Aeroporto-Hotel | R17: 7 Roads | S17: 39 | T17: 2
B18: 45022 | C18: 12h30 | D18: Rachel Reynolds | E18: 403 | F18: Hotel-Aeroporto | G18: SunDestiny | H18: 25 | I18: 7 | J18: 2 | K18: DO | M18: 45044 | N18: 08h15 | O18: Keri Potts | Q18: Aeroporto-Hotel | R18: 7 Roads | S18: 39 | T18: 2
B19: 45022 | C19: 17h25 | D19: Eric Talavet | F19: Aeroporto-Hotel | G19: SunDestiny | H19: 35 | I19: 5 | J19: 2 | K19: AR | M19: 45044 | N19: 08h20 | O19: Susan Graves | Q19: Aeroporto-Hotel | R19: 7 Roads | S19: 39 | T19: 2
B20: 45022 | C20: 15h45 | D20: Elizabeth Bucker | F20: Aeroporto-Hotel | G20: SunDestiny | H20: 35 | I20: 5 | J20: 2 | K20: DO | M20: 45045 | N20: 12h05 | O20: Joan Hillis | Q20: Aeroporto-Hotel | R20: 7 Roads | S20: 39 | T20: 2
B21: 45022 | C21: 21h25 | D21: Maria Gallo | F21: Aeroporto-Hotel | G21: SunDestiny | H21: 35 | I21: 5 | J21: 3 | K21: DO | M21: 45045 | N21: 13h30 | O21: Susan Thomson | P21: 101 | Q21: Hotel-Aeroporto | R21: 7 Roads | S21: 22 | T21: 2 | U21: Pago, mas não usufruiu.
B22: 45023 | C22: 08h20 | D22: Eric Lorenz | F22: Aeroporto-Hotel | G22: SunDestiny | H22: 35 | I22: 5 | J22: 2 | K22: DO | M22: 45046 | N22: 21h15 | O22: Nivethitha Ram Ganapathiram | Q22: Aeroporto-Hotel | R22: 7 Roads | S22: 39 | T22: 2
B23: 45023 | C23: 08h20 | D23: Carol Zimmermann | F23: Aeroporto-Hotel | G23: SunDestiny | H23: 35 | I23: 5 | J23: 2 | K23: DO
B24: 45023 | C24: 14h50 | D24: Gabi Ohlinger | F24: Aeroporto-Hotel | G24: SunDestiny | H24: 35 | I24: 5 | J24: 2 | K24: AR
B25: 45024 | C25: 04h15 | D25: Elizabeth Buckner | E25: 101 | F25: Hotel-Aeroporto | G25: SunDestiny | H25: 25 | I25: 7 | J25: 2 | K25: AR
B26: 45024 | C26: 08h30 | D26: Henriette Fredriksen | E26: 407 | F26: Hotel-Aeroporto | G26: SunDestiny | H26: 25 | I26: 7 | J26: 3 | K26: AR
B27: 45024 | C27: 09h45 | D27: Orit Bem-Sasson | F27: Aeroporto-Hotel | G27: SunDestiny | H27: 35 | I27: 5 | J27: 2 | K27: CB
B28: 45025 | C28: 05h00 | D28: Ann Brandt | E28: 205 | F28: Hotel-Aeroporto | G28: SunDestiny | H28: 25 | I28: 7 | J28: 2 | K28: AR
B29: 45026 | C29: 04h30 | D29: Paloma Coll | E29: 103 | F29: Hotel-Aeroporto | G29: SunDestiny | H29: 25 | I29: 7 | J29: 2 | K29: BM
B30: 45026 | C30: 04h45 | D30: Geir Thomas Eriksen | E30: 304 | F30: Hotel-Aeroporto | G30: SunDestiny | H30: 25 | I30: 7 | J30: 2 | K30: AR
B31: 45026 | C31: 07h30 | D31: Esther Espinosa | E31: 212 | F31: Hotel-Aeroporto | G31: SunDestiny | H31: 25 | I31: 7 | J31: 2 | K31: AR
B32: 45026 | C32: 10h15 | D32: Família Kreuter | E32: 406 + 408 | F32: Hotel-Aeroporto | G32: SunDestiny | H32: 30 | I32: 7.5 | J32: 4 | K32: AR
B33: 45026 | C33: 11h30 | D33: Maria Gallo | E33: 315 | F33: Hotel-Aeroporto | G33: SunDestiny | H33: 25 | I33: 7 | J33: 3 | K33: AS
B34: 45026 | C34: 10h50 | D34: Jason Mancini | F34: Aeroporto-Hotel | G34: SunDestiny | H34: 35 | I34: 5 | J34: 2 | K34: CB
B35: 45027 | C35: 10h30 | D35: Anthony Sorvino | F35: Aeroporto-Hotel | G35: SunDestiny | H35: 35 | I35: 5 | J35: 2 | K35: CB
B36: 45027 | C36: 11h15 | D36: Rolv Slungaard | F36: Aeroporto-Hotel | G36: SunDestiny | H36: 35 | I36: 5.002 | J36: 2 | K36: AR
B37: 45028 | C37: 06h30 | D37: Laura Schuster | F37: Hotel-Aeroporto | G37: SunDestiny | H37: 25 | I37: 7 | J37: 2 | K37: AR
B38: 45028 | C38: 10h00 | D38: Rolv Slungaard | F38: Hotel-Aeroporto | G38: SunDestiny | H38: 25 | I38: 7 | J38: 2 | K38: DO
B39: 45028 | C39: 11h30 | D39: Lawrence Santisteban | E39: 206 + 306 | F39: Hotel-Aeroporto | G39: SunDestiny | H39: 30 | I39: 7.5 | J39: 4 | K39: AR
B40: 45028 | C40: 16h25 | D40: Stan Fiorentino | F40: Aeroporto-Hotel | G40: SunDestiny | H40: 35 | I40: 5 | J40: 2 | K40: DO
B41: 45029 | C41: 08h20 | D41: Chris Larocque | F41: Aeroporto-Hotel | G41: SunDestiny | H41: 50 | I41: 10 | J41: 4 | K41: CL
...

Sheet Transfers Maio
B1: MSH ROSSIO - TRANSFERS MAIO 2023
C2: * Por favor conferir comissões de transfers pagos ao hotel e modificar cor para
B3: SUNDESTINY | F3: Rita & Pedro Lobo | G3: 962930401 | H3: 962522529 | M3: 7 Roads | Q3: Carla | R3: 939660691
B5: Data | C5: Horas | D5: Cliente | E5: Quarto | F5: Serviço | G5: Empresa | H5: Valor | I5: Comissão | J5: Nº pax | M5: Data | N5: Horas | O5: Cliente | P5: Quarto | Q5: Serviço | R5: Empresa | S5: Valor | T5: Nº pax
B6: 45047 | C6: 20h25 | D6: Tuli Gavriel | F6: Aeroporto-Hotel | G6: SunDestiny | H6: 35 | I6: 5 | J6: 1 | K6: CB | M6: 45048 | N6: 08h20 | O6: Ronald Secrist | Q6: Aeroporto-Hotel | R6: 7 Roads | S6: 39 | T6: 2
B7: 45047 | C7: 04h00 | D7: Malanie | E7: 104 | F7: Hotel-Aeroporto | G7: SunDestiny | H7: 25 | I7: 7 | J7: 2 | K7: CB | M7: 45048 | N7: 17h55 | O7: Gary Olmeim | Q7: Aeroporto-Hotel | R7: 7 Roads | S7: 39 | T7: 2
B9: 45047 | C9: 03h30 | D9: Arlene Aitkins | E9: 303 | F9: Hotel-Aeroporto | G9: SunDestiny | H9: 25 | I9: 7 | J9: 2 | K9: AR | M9: 45049 | N9: 07h00 | O9: Joan Hills | P9: 302 | Q9: Hotel-Aeroporto | R9: 7 Roads | S9: 22 | T9: 2
B10: 45048 | C10: 06h45 | D10: Mark Sebastian | E10: 205 | F10: Hotel-Aeroporto | G10: SunDestiny | H10: 30 | I10: 7.5 | J10: 2 | K10: AR | M10: 45053 | N10: 06h30 | O10: Scott Sherer | Q10: Aeroporto-Hotel | R10: 7 Roads | S10: 39 | T10: 2
B11: 45048 | C11: 11h15 | D11: Susan Graves | F11: Aeroporto-Hotel | G11: SunDestiny | H11: 35 | I11: 5 | J11: 2 | K11: AR | M11: 45054 | N11: 09h20 | O11: Gary Oman | Q11: Aeroporto-Hotel | R11: 7 Roads | S11: 39 | T11: 2
B12: 45049 | C12: 05h15 | D12: Ginette Paquin | E12: 316 | F12: Hotel-Aeroporto | G12: SunDestiny | H12: 25 | I12: 7 | J12: 2 | K12: DO | M12: 45056 | N12: 05h00 | O12: Scott Sherer | Q12: Hotel-Aeroporto | R12: 7 Roads | S12: 22 | T12: 2
B13: 45049 | C13: 06h30 | D13: Cheryl Gutierrez | E13: 204 | F13: Hotel-Aeroporto | G13: SunDestiny | H13: 25 | I13: 7 | J13: 2 | K13: AR | M13: 45056 | N13: 05h00 | O13: Ronald Brown | Q13: Hotel-Aeroporto | R13: 7 Roads | S13: 22 | T13: 2
B14: 45049 | C14: 11h00 | D14: Chin Chang | E14: 405 | F14: Hotel-Aeroporto | G14: SunDestiny | H14: 25 | I14: 7 | J14: 2 | K14: DO | M14: 45056 | N14: 10h00 | O14: Roger Brazill | Q14: Hotel-Aeroporto | R14: 7 Roads | S14: 22 | T14: 2
B15: 45049 | C15: 16h25 | D15: Stacy Fagan | E15: 210 + 212 | F15: Sete Rios - Hotel | G15: SunDestiny | H15: 50 | I15: 10 | J15: 3 | K15: DO | M15: 45060 | N15: 21h10 | O15: Joseph Eastwood | Q15: Aeroporto-Hotel | R15: 7 Roads | S15: 39 | T15: 2
B16: 45050 | C16: 06h30 | D16: Paula zindler | E16: 303 | F16: Hotel-Aeroporto | G16: SunDestiny | H16: 25 | I16: 7 | J16: 2 | K16: AS | M16: 45061 | N16: 10h35 | O16: Daniel Sullivan | Q16: Aeroporto-Hotel | R16: 7 Roads | S16: 39 | T16: 2
B17: 45050 | C17: 11h00 | D17: Annelise | E17: 211 | F17: Hotel-Aeroporto | G17: SunDestiny | H17: 25 | I17: 7 | J17: 2 | K17: AS | M17: 45063 | N17: 04h30 | O17: Atherine Rothacker | P17: 104 | Q17: Hotel-Aeroporto | R17: 7 Roads | S17: 22 | T17: 1
B18: 45050 | C18: 19h30 | D18: Nivethitha Ram Ganapathiram | E18: 402 | F18: Hotel-Aeroporto | G18: SunDestiny | H18: 25 | I18: 7 | J18: 2 | K18: AR | M18: 45063 | N18: 06h30 | O18: Hani Karout | Q18: Aeroporto-Hotel | R18: 7 Roads | S18: 39 | T18: 2
B19: 45050 | C19: 11h10 | D19: Gilles Blanchet | F19: Aeroporto-Hotel | G19: SunDestiny | H19: 35 | I19: 5 | J19: 2 | K19: AR | M19: 45064 | N19: 06h30 | O19: Catherine Wissing | P19: 301 | Q19: Hotel-Aeroporto | R19: 7 Roads | S19: 22 | T19: 2
B20: 45051 | C20: 23H15 | D20: Florence | F20: Aeroporto-Hotel | G20: SunDestiny | H20: 35 | I20: 5 | J20: 2 | K20: CB | M20: 45065 | N20: 07h30 | O20: Hannah Bucchin | P20: 201 | Q20: Hotel-Aeroporto | R20: 7 Roads | S20: 22 | T20: 2
B21: 45052 | C21: 12h05 | D21: Michael Suerth | F21: Aeroporto-Hotel | G21: SunDestiny | H21: 50 | I21: 10 | J21: 3 | K21: AR | M21: 45069 | N21: 21h35 | O21: Ryan Fansler | Q21: Aeroporto-Hotel | R21: 7 Roads | S21: 39 | T21: 2
B22: 45052 | C22: 10h00 | D22: Paula Loeb | F22: Aeroporto-Hotel | G22: SunDestiny | H22: 35 | I22: 5 | J22: 2 | K22: AS | M22: 45071 | N22: 09h20 | O22: Emilie Niquette | Q22: Aeroporto-Hotel | R22: 7 Roads | S22: 39 | T22: 2
B23: 45053 | C23: 06h10 | D23: Catherine Smith | F23: Aeroporto-Hotel | G23: SunDestiny | H23: 35 | I23: 5 | J23: 2 | K23: FP | M23: 45074 | N23: 14h35 | O23: Harriet Cook | Q23: Aeroporto-Hotel | R23: 7 Roads | S23: 39 | T23: 2
B24: 45053 | C24: 12h25 | D24: Tashri Mahabir | F24: Aeroporto-Hotel | G24: SunDestiny | H24: 35 | I24: 5 | J24: 2 | K24: AS | M24: 45075 | N24: 10h40 | O24: Jay Bower | Q24: Aeroporto-Hotel | R24: 7 Roads | S24: 39 | T24: 2
B25: 45054 | C25: 13h00 | D25: Annick | E25: 312 + 408 | F25: Hotel-Aeroporto | G25: SunDestiny | H25: 25 | I25: 7 | J25: 3 | K25: AS | M25: 45075 | N25: 11h25 | O25: Zachary Pirkl | Q25: Aeroporto-Hotel | R25: 7 Roads | S25: 39 | T25: 2
B26: 45054 | C26: 15h10 | D26: Diana Seruga Sagadin | F26: Aeroporto-Hotel | G26: SunDestiny | H26: 35 | I26: 5 | J26: 1 | K26: AR | M26: 45076 | N26: 06h30 | O26: Daiane Silva | P26: 410 | Q26: Hotel-Aeroporto | R26: 7 Roads | S26: 39 | T26: 2
B27: 45055 | C27: 08h15 | D27: Iohn Henry Niehaus | E27: 407 | F27: Hotel-Aeroporto | G27: SunDestiny | H27: 25 | I27: 7 | J27: 2 | K27: AR | M27: 45076 | N27: 10h50 | O27: Dennis Majerski | Q27: Aeroporto-Hotel | R27: 7 Roads | S27: 39 | T27: 2
B28: 45055 | C28: 23h00 | D28: Nicole Cuttat | F28: Aeroporto-Hotel | G28: SunDestiny | H28: 35 | I28: 5 | J28: 2 | K28: DO | M28: 45077 | N28: 01h00 | O28: Anat scheffer | Q28: Aeroporto-Hotel | R28: 7 Roads | S28: 39 | T28: 2
B29: 45056 | C29: 10h00 | D29: Kristen Ranaldo | F29: Aeroporto-Hotel | G29: SunDestiny | H29: 50 | I29: 10 | J29: 4 | K29: AR
B30: 45056 | C30: 14h20 | D30: Rajeshkumar Mistry | F30: Aeroporto-Hotel | G30: SunDestiny | H30: 35 | I30: 5 | J30: 1 | K30: DO
B31: 45056 | C31: 14h00 | D31: Mahabir Tashri Sandy | E31: 301 | F31: Hotel-Aeroporto | G31: SunDestiny | H31: 25 | I31: 7 | J31: 1 | K31: TS
B32: 45057 | C32: 05h15 | D32: Serena Di Cecilia | E32: 212 | F32: Hotel-Aeroporto | G32: SunDestiny | H32: 25 | I32: 7 | J32: 1 | K32: AR
B33: 45057 | C33: 11h15 | D33: Joohan Soo | F33: Aeroporto-Hotel | G33: SunDestiny | H33: 35 | I33: 5 | J33: 1 | K33: FP
B34: 45057 | C34: 11h30 | D34: Diana Seruga Sagadin | E34: 410 | F34: Hotel-Aeroporto | G34: SunDestiny | H34: 25 | I34: 7 | J34: 2 | K34: AS
B35: 45058 | C35: 05h10 | D35: Gerson | E35: 402 | F35: Hotel-Aeroporto | G35: SunDestiny | H35: 25 | I35: 7 | J35: 2 | K35: GB
B36: 45058 | C36: 14h00 | D36: Rajeshkumar Mistry | E36: 303 | F36: Hotel-Aeroporto | G36: SunDestiny | H36: 25 | I36: 7 | J36: 2 | K36: AS
B37: 45058 | C37: 13h34 | D37: Caroline O'Brien | F37: Aeroporto-Hotel | G37: SunDestiny | H37: 35 | I37: 5 | J37: 2 | K37: AR
B38: 45059 | C38: 08h20 | D38: Steve Taylor | F38: Aeroporto-Hotel | G38: SunDestiny | H38: 35 | I38: 5 | J38: 2 | K38: AS
B39: 45059 | C39: 05h30 | D39: Gbrmazur Nataliia | E39: 407 | F39: Hotel-Aeroporto | G39: SunDestiny | H39: 25 | I39: 7 | J39: 1 | K39: DT/TS
B40: 45059 | C40: 11h00 | D40: Peter Worley | F40: Aeroporto-Hotel | G40: SunDestiny | H40: 35 | I40: 5 | J40: 2 | K40: DT/TS
B41: 45059 | C41: 08h20 | D41: Theresa Oberle | F41: Aeroporto-Hotel | G41: SunDestiny | H41: 50 | I41: 10 | J41: 4 | K41: AR
B42: 45060 | C42: 09h25 | D42: Sarah Kirk | F42: Aeroporto-Hotel | G42: SunDestiny | H42: 35 | I42: 5 | J42: 2 | K42: AR
...

Sheet Toursss
B2: Data | C2: Horas | D2: Cliente | E2: Quarto | F2: Serviço | G2: Empresa | H2: Valor | I2: Comissão | J2: Nº pax
B3: 44930 | C3: 08h10 | D3: Christelle Vacilotto | E3: 410 | F3: Tour Sintra | G3: Where To | H3: 130 | I3: 39 | J3: 2 | K3: AR
B4: 44931 | C4: 08h00 | D4: José Luis Fraile | E4: 201 + 205 | F4: Tour Sintra | G4: Where To | H4: 260 | I4: 78 | J4: 4 | K4: Ana
B5: 44944 | C5: 08h15 | D5: John Fanner | E5: 302 | F5: Tour Fatima | G5: Where To | H5: 158 | I5: =+H5*0.3 -> 47.4 | J5: 2 | K5: DO
B6: 44948 | C6: 08h15 | D6: Corina | E6: 208 + 216 | F6: Tour Sintra | G6: Celina | H6: 300 | I6: 75 | J6: 4 | K6: AS
B7: 44986 | C7: 08h00 | D7: Sally Sommonds | E7: 311 | F7: Tour Sintra | G7: Where To | H7: 130 | I7: 39 | J7: 2 | K7: CB/AR
B8: 44988 | C8: 08h20 | D8: Thomas Briola | E8: 415 | F8: Tour Fátima | G8: Where To | H8: 158 | I8: 47.4 | J8: 2 | K8: AR
B9: 45006 | C9: 08h15 | D9: Chantal Guiguere | E9: 208 + 210 | F9: Tour Sintra | G9: Where To | H9: 130 | I9: 39 | J9: 2 | K9: AS
B10: 45008 | C10: 08h15 | D10: Elad Cohen | E10: 408 | F10: Tour Sintra | G10: Where To | H10: 65 | I10: 19.5 | J10: 1 | K10: AS
B11: 45010 | C11: 08h30/09h | D11: Gian Luca Casolari | E11: 407 | F11: Tour Sintra | G11: Yellow Cab | H11: 118 | I11: 33 | J11: 2 | K11: AR
B12: 45011 | C12: 08h30/09h | D12: Ece Demirkir Cakir | E12: 412 | F12: Tour Sintra | G12: Yellow Cab | H12: 59 | I12: 16.5 | J12: 1 | K12: AR
B13: 45014 | C13: 08h15 | D13: Silvia Licini | E13: 215 | F13: Tour Sintra | G13: Where To | H13: 130 | I13: 39 | J13: 2 | K13: DO
B14: 45020 | C14: 08h30/09h | D14: Ali Paydas | E14: 216 | F14: Tour Sintra | G14: Yellow Cab | H14: 118 | I14: 33 | J14: 2 | K14: AR
B15: 45021 | C15: 08h30/09h | D15: Gerald Schneider | E15: 316 | F15: Tour Sintra | G15: Yellow Cab | H15: 118 | I15: 33 | J15: 2 | K15: DO | M15: COMISSÃO VOX CITY: 20% (TOURS, TUK, BOATS, ESCAPE HUNT, ETC..)
B16: 45029 | C16: 08h30/09h | D16: Aasne Bjornsen | E16: 304 | F16: Tour Sintra | G16: Yellow Cab | H16: 118 | I16: 33 | J16: 2 | K16: TS
B17: 45034 | C17: 08h30/09h | D17: Eliana Marques | E17: 208 | F17: Tour Fátima | G17: Yellow Cab | H17: 148 | I17: 35 | J17: 2 | K17: AR | M17: COMISSÃO CELINA TOURS: 25%
B18: 45036 | C18: 08h30/09h | D18: Eliana Marques | E18: 208 | F18: Tour Sintra | G18: Yellow Cab | H18: 118 | I18: 33 | J18: 2 | K18: AR
B19: 45039 | C19: 08h30/09h | D19: Zhiyong He | E19: 402 | F19: Tour Sintra | G19: Yellow Cab | H19: 118 | I19: 33 | J19: 2 | K19: AS | M19: COMISSÃO WHERE TO: 30%
B20: 45047 | C20: 08h00 | D20: Carmen | E20: 203 | F20: Tour Sintra | G20: Where To | H20: 130 | I20: 39 | J20: 2 | K20: CB
B21: 45055 | C21: 08h00 | D21: Sherer | E21: 316 + 415 | F21: Tour Sintra | G21: Where To | H21: 236 | I21: =+H21*0.3 -> 70.8 | J21: 4 | K21: AS | M21: COMISSÃO YELLOW CAB:
B22: 45063 | C22: 08h30/09h | D22: Marcia Lacerda | E22: 409 | F22: Tour Sintra | G22: Yellow Cab | H22: 118 | I22: 33 | J22: 2 | K22: DO
B23: 45067 | C23: 08h30/09h | D23: Serafina Guanci | E23: 403 | F23: Tour Sintra | G23: Yellow Cab | H23: 118 | I23: 33 | J23: 2 | K23: TS/CB
B24: 45070 | C24: 08h30/09h | D24: Alejandro Lara | E24: 211 | F24: Tour Fátima | G24: Yellow Cab | H24: 148 | I24: 35 | J24: 2 | K24: AR
B25: 45072 | C25: 08h00 | D25: Shaw | E25: 409 + 412 | F25: Tour Sintra | G25: Where To | H25: 236 | I25: 70.8 | J25: 4 | K25: CB
B26: 45082 | C26: 08h30/09h | D26: Jean Rosemarie Maver | E26: 209 | F26: Tour Sintra | G26: Yellow Cab | H26: 118 | I26: 33 | J26: 2 | K26: TS
B27: 45092 | C27: 08h30/09h | D27: Elizabeth De Amorim Bueno Vieira | E27: 411 | F27: Tour Fátima | G27: Yellow Cab | H27: 148 | I27: 35 | J27: 2 | K27: TS
B28: 45106 | C28: 08h30/09h | D28: Julia Krottenhart | E28: 410 | F28: Tour Sintra | G28: Yellow Cab | H28: 118 | I28: 33 | J28: 2 | K28: TS
B29: 45117 | C29: 08h30/09h | E29: 315 | F29: Tour Sintra | G29: Yellow Cab | H29: 127.5 | I29: 49.5 | J29: 3 | K29: CB
B30: 45131 | C30: 08h30/09h | D30: Renad Alowayyid | E30: 302 | F30: Tour Sintra | G30: Yellow Cab | H30: 118 | I30: 33 | J30: 2 | K30: AR
B31: 45136 | C31: 08h15 | D31: Penelope White / Thomas White | E31: 408 | F31: Tour Sintra | G31: Where To | H31: 130 | I31: 39 | J31: 2 | K31: TS/IC
B32: 45138 | C32: 08h15 | D32: Cláudia Valredo | E32: 208 + 210 | F32: Tour Sintra | G32: Where To | H32: 236 | I32: 70.8 | J32: 4 | K32: AR/TS
B33: 45139 | C33: 08h15 | D33: Cláudia Valredo | E33: 208 + 210 | F33: Tour Fatima | G33: Where To | H33: 300 | I33: =H33*30% -> 90 | J33: 4 | K33: AR/TS
B34: 45147 | C34: 08h30 | D34: Deborah Kane | E34: 412 | F34: Tour Sintra | G34: Yellow Cab | H34: 59 | I34: 16.5 | J34: 1 | K34: TS/JG
B35: 45154 | C35: 08h30h/09h | D35: Daniel Brickman | E35: 409 | F35: Tour Sintra | G35: Yellow Cab | H35: 118 | I35: 33 | J35: 2 | K35: AR
B36: 45156 | C36: 08h30 | D36: Rene | E36: 206 | F36: Tour Sintra | G36: Yellow Cab | H36: 118 | I36: 33 | J36: 2 | K36: AS/IC
B37: 45160 | C37: 08h15 | D37: Jean Pimlett | E37: 302 | F37: Tour Sintra | G37: Where To | H37: 130 | I37: 39 | J37: 2 | K37: DO
B38: 45170 | C38: 08h10 | D38: Sarrasin Justin | E38: 406 | F38: Tour Sintra | G38: Where To | H38: 130 | I38: 39 | J38: 2 | K38: JG
B39: 45174 | C39: 08h20 | D39: Linqa Jfan Yomng | E39: 207 | F39: Tour Fátima | G39: Yellow Cab | H39: 148 | I39: 35 | J39: 2 | K39: JG
B40: 45174 | C40: 08h30/09h | D40: Philip Lewis | E40: 311 | F40: Tour Sintra | G40: Yellow Cab | H40: 118 | I40: 33 | J40: 2 | K40: AR
B41: 45175 | C41: 08h20 | D41: Mohamed Bouchlain | E41: 303 | F41: Tour Sintra | G41: Where To | H41: 130 | I41: 39 | J41: 2 | K41: DO
...

Sheet Gratificações
A1: JANEIRO | E1: FEVEREIRO | I1: MARÇO | M1: ABRIL | Q1: MAIO | U1: JUNHO | Y1: JULHO | AC1: AGOSTO | AG1: SETEMBRO | AK1: OUTUBRO | AO1: NOVEMBRO | AS1: DEZEMBRO | AW1: Janeiro | BA1: Fevereiro | BE1: Março | BI1: Abril | BM1: Maio | BQ1: Junho | BU1: Julho | BY1: Agosto | CC1: Setembro | CG1: Outubro | CK1: Novembro | CO1: Dezembro | CS1: Janeiro 2025 | CW1: Fevereiro 2025 | DA1: Março 2025 | DE1: 16 Setembro 25 A 15 Outubro 25 | DJ1: 15 Outubro 25 A 15 Novembro 25 | DT1: 16 Setembro 25 A 15 Outubro 25
A2: Data | B2: Designação | C2: Valor | D2: Recepcionista | E2: Data | F2: Designação | G2: Valor | H2: Recepcionista | I2: Data | J2: Designação | K2: Valor | L2: Recepcionista | M2: Data | N2: Designação | O2: Valor | P2: Recepcionista | Q2: Data | R2: Designação | S2: Valor | T2: Recepcionista | U2: Data | V2: Designação | W2: Valor | X2: Recepcionista | Y2: Data | Z2: Designação | AA2: Valor | AB2: Recepcionista | AC2: Data | AD2: Designação | AE2: Valor | AG2: Data | AH2: Designação | AI2: Valor | AJ2: Recepcionista | AK2: Data | AL2: Designação | AM2: Valor | AN2: Recepcionista | AO2: Data | AP2: Designação | AQ2: Valor | AR2: Recepcionista | AS2: Data | AT2: Designação | AU2: Valor | AV2: Recepcionista | AW2: Data | AX2: Designação | AY2: Valor | AZ2: Recepcionista | BA2: Data | BB2: Designação | BC2: Valor | BD2: Recepcionista | BE2: Data | BF2: Designação | BG2: Valor | BH2: Recepcionista | BI2: Data | BJ2: Designação | BK2: Valor | BL2: Recepcionista | BM2: Data | BN2: Designação | BO2: Valor | BP2: Recepcionista | BQ2: Data | BR2: Designação | BS2: Valor | BT2: Recepcionista | BU2: Data | BV2: Designação | BW2: Valor | BX2: Recepcionista | BY2: Data | BZ2: Designação | CA2: Valor | CB2: Recepcionista | CC2: Data | CD2: Designação | CE2: Valor | CF2: Recepcionista | CG2: Data | CH2: Designação | CI2: Valor | CJ2: Recepcionista | CK2: Data | CL2: Designação | CM2: Valor | CN2: Recepcionista | CO2: Data | CP2: Designação | CQ2: Valor | CR2: Recepcionista | CS2: Data | CT2: Designação | CU2: Valor | CV2: Recepcionista | CW2: Data | CX2: Designação | CY2: Valor | CZ2: Recepcionista | DA2: Data | DB2: Designação | DC2: Valor | DD2: Recepcionista | DE2: data | DF2: Designação | DG2: Valor | DH2: Recepcionista | DJ2: Recepcionista | DK2: Data | DL2: Designação | DM2: Valor | DN2: Recepcionista | DO2: Data | DP2: Designação | DQ2: Valor | DR2: Recepcionista | DT2: data | DU2: Designação | DV2: Valor | DW2: Recepcionista | DX2: Total comissão | DY2: =+DQ47+DY7+DY8+DY9+DY10+DY6+EB2+DY11 -> 55.31 | EA2: Sobras Tips | EB2: 121.79
A3: 44928 | B3: Where To Comissão | C3: 39 | D3: Andreia | E3: 44958 | F3: Saldo Janeiro | G3: =+C72-C103 -> 1.85 | H3: Daniela | I3: 44986 | J3: Saldo Fevereiro | K3: 0.72 | L3: Daniela | M3: 44986 | N3: Saldo Março | O3: 0.95 | P3: Daniela | Q3: 44986 | R3: Saldo Março | S3: =1171.13-1168 -> 3.13 | T3: Daniela | U3: 45078 | V3: Saldo Maio | W3: 3.67 | X3: Daniela | Y3: 45118 | Z3: Saldo Julho | AA3: 10.67 | AB3: Afonso/Andreia | AC3: 45144 | AD3: Comissão DSCAR | AE3: 18 | AF3: Afonso/Andreia | AG3: 45170 | AH3: TIP 212 | AI3: 10 | AJ3: Afonso | AK3: 45200 | AL3: TIP 316 | AM3: 4 | AN3: Inês | AO3: 45231 | AP3: Celina tours comissão | AQ3: 44.5 | AR3: Cristiana | AS3: 45263 | AT3: TIP Passante | AU3: 5 | AV3: Afonso | AW3: 45293 | AX3: TIP 101 | AY3: 2 | AZ3: Tomás | BA3: 45324 | BB3: Comissão Cooptáxis | BC3: 2.02 | BD3: Andreia/Inês | BE3: 45354 | BF3: Comissão Where To | BG3: 39 | BH3: Afonso/Tomás | BI3: 45385 | BJ3: Comissão Monte Mar | BK3: 10 | BL3: Andreia | BM3: 45413 | BN3: tip 216 | BO3: 5 | BP3: Cris | BQ3: 45444 | BR3: Sofá | BS3: 1.5 | BT3: Renato | BU3: 45474 | BV3: Comissão YellowCab | BW3: 38 | BX3: Tomás | BY3: 45505 | BZ3: Comissão YellowCab | CA3: 40 | CB3: Afonso | CC3: 45537 | CD3: Comissao Yellow Cab | CE3: 40 | CF3: Inês | CG3: 45566 | CH3: WC | CI3: 0.5 | CJ3: Cris | CK3: 45597 | CL3: TIP 416 | CM3: 10 | CN3: Afonso | CO3: 45630 | CP3: TIP 316 | CQ3: 4 | CR3: Inês | CS3: 45659 | CT3: TIP SOFÁ | CU3: 2 | CV3: Afonso | CW3: 45694 | CX3: TIP 307 | CY3: 10 | CZ3: Afonso | DA3: 45720 | DB3: TIP | DC3: 10 | DD3: Inês | DE3: 45916 | DF3: Sobra o mês passado | DG3: 5.5 | DH3: Pedro | DO3: 45992 | DP3: A mais | DQ3: 108.5 | DR3: Erica | DX3: Número de recepcionistas | DY3: 10 | EA3: Falta repor | EB3: 738.8
A4: 44930 | B4: Tip 405 | C4: 1 | D4: Daniela | E4: 44958 | F4: TIP 306 | G4: 1.5 | H4: Daniela | I4: 44986 | J4: Comissão Where To | K4: 39 | L4: Daniela | M4: 45017 | N4: tip 205 | O4: 10.1 | P4: Cristiana | Q4: 45048 | R4: TIP #201 | S4: 3 | T4: Andreia | U4: 45078 | V4: TIP 315 | W4: 5 | X4: Cristiana | Y4: 45110 | Z4: TIP 203 | AA4: 5 | AB4: Afonso/Andreia | AC4: 45145 | AD4: TIP 307 | AE4: 5 | AF4: Tomás/Joana/Andreia | AG4: 45171 | AH4: TIP 415 | AI4: 5 | AJ4: Afonso | AK4: 45201 | AL4: TIP 308 | AM4: 5 | AN4: Inês | AO4: 45231 | AP4: Yellow Cab Fatima | AQ4: 35 | AR4: Cristiana | AS4: 45264 | AT4: Comissao Where to | AU4: 39 | AV4: Inês | AW4: 45292 | AX4: TIP 104 | AY4: 10 | AZ4: Cris | BA4: 45327 | BB4: Comissão Where To | BC4: 19.5 | BD4: Tomás | BE4: 45354 | BF4: Valor de sobra do mês passado | BG4: 8 | BH4: Afonso | BI4: 45385 | BJ4: TIP 202 | BK4: 2 | BL4: Andreia | BM4: 45413 | BN4: tip 103 | BO4: 2 | BP4: Cris | BQ4: 45446 | BR4: Sofá | BS4: 2 | BT4: Andreia | BU4: 45475 | BV4: TIP 316 | BW4: 100 | BX4: Afonso | BY4: 45505 | BZ4: TIP 404 | CA4: 3 | CB4: Cris/Andreia | CC4: 45538 | CD4: TIP 404 | CE4: 2 | CF4: Afonso | CG4: 45566 | CH4: HOSPEDE | CI4: 1.5 | CJ4: Cris | CK4: 45597 | CL4: TIP | CM4: 2 | CN4: Inês | CO4: 45632 | CP4: Impressora | CQ4: 1.5 | CR4: Cris | CS4: 45660 | CT4: TIP Casa de Banho | CU4: 1 | CV4: Afonso | CW4: 45695 | CX4: TIP 315 | CY4: 3 | CZ4: Ivan | DA4: 45720 | DB4: Tour Sintra #206+#209 | DC4: 38 | DD4: Inês/Afonso | DO4: 45993 | DP4: A menos (CitySightSeeing) | DQ4: -27 | DR4: Erica | DX4: Tips p/ pessoa | DY4: =+DY2/DY3 -> 5.531
A5: 44931 | B5: Where To Comissão | C5: 78 | D5: Daniela | E5: 44963 | F5: Falta caixa | G5: -1.13 | H5: Daniela | I5: 44986 | J5: Sobra caixa | K5: 6.12 | L5: Daniela | M5: 45018 | N5: TIP 416 | O5: 11 | P5: Cristiana/Tomás | Q5: 45025 | R5: Falta caixa | S5: -1 | T5: Daniela | U5: 45078 | V5: Fado in Chiado | W5: 6 | X5: Cristiana | Y5: 45110 | Z5: TIP 307 | AA5: 5 | AB5: Afonso/Andreia | AC5: 45146 | AD5: Saldo Julho | AE5: 1.48 | AF5: Daniela | AG5: 45171 | AH5: TIP 104+103 | AI5: 20 | AJ5: Afonso | AK5: 45201 | AL5: Comissão Where To | AM5: 39 | AN5: Afonso/Andreia | AO5: 45233 | AP5: TIP 204 | AQ5: 5 | AR5: Inês | AS5: 45265 | AT5: TIP 302 | AU5: 10 | AV5: Tomás | AW5: 45292 | AX5: Comissão where to | AY5: 90 | AZ5: Cris | BA5: 45329 | BB5: Comissão Trovas Antigas | BC5: 10 | BD5: Cris | BE5: 45354 | BF5: TIP 102 | BG5: 2 | BH5: Cris | BI5: 45385 | BJ5: Tip 316 - assistencia ao # | BK5: 5 | BL5: Cris | BM5: 45413 | BN5: Comissão tour 03/05 | BO5: 41.4 | BP5: Cris | BQ5: 45453 | BR5: TIP 306 | BS5: 30 | BT5: Afonso | BU5: 45476 | BV5: TIP 202 | BW5: 10 | BX5: Inês | BY5: 45506 | BZ5: TIP 315 | CA5: 8 | CB5: Afonso | CC5: 45538 | CD5: TIP 205 | CE5: 4 | CF5: Afonso | CG5: 45567 | CH5: TIP #303 | CI5: 20 | CJ5: Afonso | CK5: 45598 | CL5: Comissão Trovas Antigas | CM5: 35 | CN5: Andreia | CO5: 45633 | CP5: TIP 401 | CQ5: 5.12 | CR5: Afonso | CS5: 45661 | CT5: Comissão tuktuk | CU5: 20 | CV5: Andreia | CW5: 45696 | CX5: A Severa | CY5: 5 | CZ5: Andreia | DA5: 45721 | DB5: TIP 303 | DC5: 2 | DD5: Afonso | DO5: 45994 | DP5: A menos | DQ5: -1.4 | DR5: Helder
A6: 44931 | B6: Tip 312 | C6: 1 | D6: Daniela | E6: 44964 | F6: Comissão A Severa | G6: 20 | H6: Daniela | I6: 44987 | J6: Comissao Where To | K6: 47.4 | L6: Afonso | M6: 45019 | N6: Comissão Yellow Cab | O6: 33 | P6: Daniela/Tomás | Q6: 45051 | R6: TIP #403 | S6: 5.24 | T6: Daniela | U6: 45078 | V6: TIP 316 | W6: 5 | X6: Tomás | Y6: 45110 | Z6: TIP 305 | AA6: 10 | AB6: Afonso/Andreia | AC6: 45146 | AD6: TIP | AE6: 1.7 | AF6: Daniela | AG6: 45172 | AH6: TIP 305 | AI6: 5 | AJ6: Tomás/Andreia | AK6: 45202 | AL6: Comissão Yellow Cab | AM6: 33 | AN6: Tomás/Cristiana | AO6: 45233 | AP6: TIP 405 | AQ6: 5 | AR6: Afonso | AS6: 45265 | AT6: TIP 202 | AU6: 10 | AV6: Afonso | AW6: 45293 | AX6: TIP passante | AY6: =3.3+1.22 -> 4.52 | AZ6: Afonso | BA6: 45329 | BB6: TIP 403 | BC6: 5 | BD6: Cris | BE6: 45356 | BF6: tip 410 | BG6: 3 | BH6: Tomás | BI6: 45386 | BJ6: Tip 316 - assistencia ao # | BK6: 5 | BL6: Cris | BM6: 45414 | BN6: TIP 402 | BO6: 10 | BP6: Andreia | BQ6: 45453 | BR6: Valor dado o mês passado | BS6: -12.88 | BT6: Afonso | BU6: 45476 | BV6: TIP 411 | BW6: 5 | BX6: Inês | BY6: 45507 | BZ6: TIP 405 | CA6: 5 | CB6: Eduardo | CC6: 45540 | CD6: TIP405 | CE6: 10 | CF6: Afonso | CG6: 45569 | CH6: Comissão Where to | CI6: 41.4 | CJ6: Inês | CK6: 45600 | CL6: Tip #303 | CM6: 2 | CN6: Ivan | CO6: 45635 | CP6: VALOR EM SOBRA OUTUBRO | CQ6: 1.48 | CR6: Afonso | CS6: 45663 | CT6: TIP 203 | CU6: 10 | CV6: Afonso | CW6: 45699 | CX6: TIP 315 | CY6: 10 | CZ6: Cris | DA6: 45724 | DB6: Tip 208 | DC6: 2 | DD6: Ivan | DO6: 45994 | DP6: A menos (decorações de natal - A repor) | DQ6: -97.92 | DR6: Erica | DX6: Comissão LS | DY6: =SUMIFS('LS Dez'!J2:J117, 'LS Dez'!C2:C117, "*LS*", 'LS Dez'!L2:L117, "Sim ") -> 118
A7: 44932 | B7: TIP 406 | C7: 2.5 | D7: Afonso | E7: 44971 | F7: TIP 312 | G7: 4 | H7: Cristiana | I7: 44988 | J7: Taxas 201 não lançadas ao c-in | K7: -6 | L7: Cristiana | M7: 45020 | N7: TIP #101 + #104 | O7: 5 | P7: Afonso | Q7: 45052 | R7: TIP #405 | S7: 20 | T7: Afonso | U7: 45078 | V7: Tip 215 | W7: 6 | X7: Tomás | Y7: 45111 | Z7: TIP 316 | AA7: 5 | AB7: Tomás | AC7: 45146 | AD7: Comissão Mar ao Carmo | AE7: 42 | AF7: Tomás | AG7: 45172 | AH7: TIP 405 | AI7: 20 | AJ7: Tomás/Afonso | AK7: 45203 | AL7: Comissão Yellow Cab | AM7: 66 | AN7: Afonso/Andreia | AO7: 45233 | AP7: TIP 208 | AQ7: 20 | AR7: Afonso | AS7: 45265 | AT7: Saldo Novembro | AU7: 7.86 | AV7: Afonso | AW7: 45294 | AX7: TIP 103 | AY7: 10 | AZ7: Tomás | BA7: 45330 | BB7: TIP 215 | BC7: 2 | BD7: Tomás | BE7: 45358 | BF7: TIP 410 | BG7: 5 | BH7: Inês | BI7: 45387 | BJ7: Tip 204 | BK7: 5 | BL7: Cris | BM7: 45415 | BN7: A mais na caixa | BO7: 4 | BP7: Inês | BQ7: 45455 | BR7: Nota perdida | BS7: 20 | BT7: Tomás | BU7: 45477 | BV7: comissão Monte Mar | BW7: 10 | BX7: Inês | BY7: 45508 | BZ7: City Tax | CA7: -4 | CB7: Inês | CC7: 45540 | CD7: Comissão YellowCab | CE7: 45 | CF7: Andreia | CG7: 45569 | CH7: Tip OUT 202+215 | CI7: 15 | CJ7: Inês | CK7: 45604 | CL7: TIP 316 | CM7: 10 | CN7: Inês | CO7: 45635 | CP7: Tip 204 | CQ7: 15 | CR7: Afonso | CS7: 45663 | CT7: Comissão dada o mês passado | CU7: -12.81 | CV7: Afonso | CW7: 45700 | CX7: Comissão Fado in Chiado | CY7: 15 | CZ7: Inês | DA7: 45724 | DB7: Tip 207 | DC7: 5 | DD7: João | DO7: 45995 | DP7: A mais | DQ7: 3 | DR7: Helder | DX7: Comissão 7Roads | DY7: =SUMIFS('7 Roads Dez'!J2:J117, '7 Roads Dez'!C2:C117, "*7Roads*", '7 Roads Dez'!L2:L117, "Sim ") -> 247
A8: 44933 | B8: Dinheiro a mais | C8: =0.15+0.25 -> 0.4 | D8: Andreia | E8: 44983 | F8: TIP 404 | G8: 4 | H8: Cristiana | I8: 44989 | J8: Sobra caixa | K8: 5 | L8: Daniela | M8: 45020 | N8: Comissão Yellow Cab | O8: 33 | P8: Cristiana | Q8: 45054 | R8: TIP 315 | S8: 5 | T8: Afonso | U8: 45079 | V8: TIP 315 | W8: 5 | X8: Tomás | Y8: 45115 | Z8: TIP 410 | AA8: 1 | AB8: Afonso | AC8: 45146 | AD8: Comiissão Yellow Cab | AE8: 16.5 | AF8: Tomás/Joana | AG8: 45173 | AH8: Saldo Agosto | AI8: 2.63 | AJ8: Daniela | AK8: 45203 | AL8: TIP 415 | AM8: 10 | AN8: Afonso/Andreia | AO8: 45233 | AP8: Ajuste de contas | AQ8: -0.21 | AR8: Tomás | AS8: 45266 | AT8: Valor dado o mês passado | AU8: =-44 -> -44 | AV8: Afonso | AW8: 45297 | AX8: TIP 306 + 309 | AY8: 10 | AZ8: Andreia | BA8: 45332 | BB8: TIP 312 | BC8: 4 | BD8: Cris | BE8: 45358 | BF8: TIP | BG8: 1.4 | BH8: Inês | BI8: 45387 | BJ8: TIP 316 | BK8: 10 | BL8: Cris | BM8: 45415 | BN8: Conversão Dólar-Euro | BO8: 6.09 | BP8: Afonso | BQ8: 45457 | BR8: TIP 404 | BS8: 20 | BT8: Afonso | BU8: 45478 | BV8: Dinheiro a mais | BW8: 0.48 | BX8: Andreia | BY8: 45509 | BZ8: Whero to fatima | CA8: 25.2 | CB8: Cris | CC8: 45541 | CD8: TIP 205 | CE8: 10 | CF8: Afonso | CG8: 45568 | CH8: Tip 203 | CI8: 30 | CJ8: Renato/Ivan | CK8: 45604 | CL8: VALOR EM SOBRA OUTUBRO | CM8: 4.68 | CN8: Afonso | CO8: 45636 | CP8: TIP 404 | CQ8: 20 | CR8: Afonso | CS8: 45664 | CT8: Comissão where TO | CU8: 38.4 | CV8: Afonso | CW8: 45700 | CX8: Tip 416 | CY8: 2 | CZ8: Ivan | DA8: 45724 | DB8: Comissão dada o mês passado | DC8: -4.75 | DD8: Afonso | DO8: 45998 | DP8: A mais | DQ8: 6.2 | DR8: Helder | DX8: Comissão CitySightSeeing | DY8: =SUM(CitySightSeeing!E3:E37) -> 33
A9: 44933 | B9: TIP 303 | C9: 5 | D9: Afonso | E9: 44985 | F9: Comissões Lisboa em Fado | G9: 8 | H9: Andreia | I9: 44990 | J9: TIP 103 | K9: 5 | L9: Afonso | M9: 45020 | N9: Tip 208 | O9: 5 | P9: Cristiana | Q9: 45054 | R9: TIP | S9: 1.35 | T9: Andreia | U9: 45079 | V9: Tip passante | W9: 5 | X9: Tomás | Y9: 45116 | Z9: TIP 415+404 | AA9: 20 | AB9: Afonso/Tomás | AC9: 45147 | AD9: Hóspede 412 | AE9: -15 | AF9: Afonso | AG9: 45173 | AH9: Comissão Where To | AI9: 39 | AJ9: Daniela | AK9: 45204 | AL9: TIP 216 | AM9: 3 | AN9: Inês | AO9: 45235 | AP9: TIP 203 | AQ9: 2.5 | AR9: Waleed | AS9: 45267 | AT9: Comissao Where to | AU9: 35 | AV9: Cristiana | AW9: 45297 | AX9: TIP 316 | AY9: 10 | AZ9: Andreia | BA9: 45333 | BB9: Ajuste caixa | BC9: 0.5 | BD9: Renato | BE9: 45358 | BF9: TIP 415 | BG9: 20 | BH9: Afonso | BI9: 45387 | BJ9: TIP 316 | BK9: 5 | BL9: Andreia | BM9: 45415 | BN9: TIP 101 | BO9: 5 | BP9: Afonso | BQ9: 45457 | BR9: TIP 203 | BS9: 2.5 | BT9: Ines | BU9: 45481 | BV9: Dinheiro no chão | BW9: 2 | BX9: Tomás | BY9: 45510 | BZ9: TIP 210 | CA9: 8 | CB9: Cris | CC9: 45450 | CD9: TIP 402+303 | CE9: 10 | CF9: Cris | CG9: 45570 | CH9: Tip 210 | CI9: 4 | CJ9: Ivan | CK9: 45604 | CL9: Troca Dollar-Euro | CM9: 13.2 | CN9: Afonso | CO9: 45636 | CP9: Comissão Yellow Cab | CQ9: 40 | CR9: Afonso | CS9: 45666 | CT9: Tip 407 | CU9: 5 | CV9: Ivan | CW9: 45701 | CX9: TIP 309 + 312 | CY9: 2.5 | CZ9: Andreia | DA9: 45726 | DB9: TIP SOFÁ | DC9: 2.95 | DD9: Renato | DJ9: Pedro | DK9: 45821 | DL9: Sobra o mês passado | DM9: 15.7 | DN9: Pedro | DO9: 46000 | DP9: A mais | DQ9: 10 | DR9: Erica | DX9: Comissão Where To | DY9: =SUM(Tours!H5:H25) -> 329.5
A10: 44934 | B10: TIP 207 | C10: 10 | D10: Flávio | E10: 44990 | F10: Sundestiny | G10: 327.5 | H10: Cristiana | I10: 44991 | J10: TIP 306 /303 | K10: 15.11 | L10: Afonso | M10: 45021 | N10: TIP passante | O10: 20 | P10: Tomás | Q10: 45054 | R10: Comissão Where To | S10: 70.8 | T10: Daniela | U10: 45080 | V10: Tip 416 | W10: 4 | X10: Tomás | Y10: 45117 | Z10: TIP 210 | AA10: 5 | AB10: Tomás | AC10: 45149 | AD10: TIP 408 | AE10: 1.5 | AF10: Joana/Tomás | AG10: 45173 | AH10: Comissão YellowCab | AI10: 33 | AJ10: Tomás/Joana | AK10: 45206 | AL10: Comissão CitySightSeeing | AM10: 182.5 | AN10: Tomás | AO10: 45235 | AP10: TIP 309 | AQ10: 4.5 | AR10: Inês | AS10: 45267 | AT10: Comissão Restaurantes (mar ao carmo, sacramento…) | AU10: 92 | AV10: Tomás | AW10: 45298 | AX10: Valor dado o mês passado | AY10: -0.34 | AZ10: Afonso | BA10: 45334 | BB10: Comissão Tour (direto) | BC10: 15 | BD10: Cris | BE10: 45358 | BF10: TIP 207 | BG10: 1 | BH10: Afonso | BI10: 45388 | BJ10: tip 209 | BK10: 7 | BL10: Tomás | BM10: 45416 | BN10: TIP Hóspede | BO10: 2 | BP10: Andreia | BQ10: 45457 | BR10: TROVAS | BS10: 20 | BT10: INES | BU10: 45481 | BV10: Comissão Where To | BW10: 71.1 | BX10: Afonso | BY10: 45510 | BZ10: Troca Dollar-Euro | CA10: 9.6 | CB10: Afonso | CC10: 45543 | CD10: TIP 410 + 415 | CE10: 20 | CF10: Cris | CG10: 45571 | CH10: Tip 305 | CI10: 10 | CJ10: Ivan | CK10: 45606 | CL10: TIP Grupo | CM10: 0.5 | CN10: Afonso | CO10: 45637 | CP10: tip #211 | CQ10: 2 | CR10: Ivan | CS10: 45303 | CT10: a + na caixa | CU10: 1 | CV10: Inês | CW10: 45702 | CX10: Comissões Mar ao Carmo | CY10: 130 | CZ10: Andreia | DA10: 45726 | DB10: TIP 304 | DC10: 10 | DD10: João | DO10: 46001 | DP10: A mais | DQ10: 54 | DR10: Erica | DX10: Comissão TukTuk | DY10: =SUM(Tours!I30:I49) -> 0
A11: 44940 | B11: TIP 415 | C11: 3.2 | D11: AS/CB | I11: 44992 | J11: TIP 303 | K11: 5.6 | L11: Afonso | M11: 45022 | N11: TIP 212 | O11: 5 | P11: Cristiana | Q11: 45057 | R11: Comissão Trovas Antigas | S11: 10 | T11: Daniela | U11: 45080 | V11: Tip 415 | W11: 3 | X11: Tomás | Y11: 45118 | Z11: Comissão Fado In Chiado | AA11: 15 | AB11: Tomás | AC11: 45150 | AD11: TIP 301 | AE11: 5 | AF11: Tomás | AG11: 45173 | AH11: Comissão YellowCab | AI11: 35 | AJ11: Joana | AK11: 45206 | AL11: TIP 401 | AM11: 2 | AN11: Tomás/Inês | AO11: 45235 | AP11: Comissão Where To | AQ11: 39 | AR11: Inês | AS11: 45268 | AT11: Acerto caixa | AU11: -2 | AV11: Fábio | AW11: 45299 | AX11: TIP 312 | AY11: 10 | AZ11: Cris | BA11: 45336 | BB11: TIP 302 | BC11: 6.9 | BD11: Inês | BE11: 45359 | BF11: Taxas Turisticas não pagas | BG11: -8 | BH11: Afonso | BI11: 45298 | BJ11: tip 316 | BK11: 5 | BL11: Tomás | BM11: 45419 | BN11: TIP 202 + 212 | BO11: 5 | BP11: Andreia | BQ11: 45457 | BR11: ajuda ao hospede | BS11: 5 | BT11: ines | BU11: 45482 | BV11: Valor dado o mês passado | BW11: -2.54 | BX11: Afonso | BY11: 45510 | BZ11: Renato (Autorizado-Afonso) | CA11: -8 | CB11: Afonso | CC11: 45543 | CD11: TIP C-OUT | CE11: 4 | CF11: Renato | CG11: 45572 | CH11: Comissão YellowCab | CI11: 57 | CJ11: Inês | CK11: 45608 | CL11: Comissão Where To | CM11: 84 | CN11: Ivan/Andreia | CO11: 45640 | CP11: Comissão Fado in Chiado | CQ11: 6 | CR11: Afonso | CS11: 45672 | CT11: Comissão YellowCab | CU11: 38 | CV11: Ivan | CW11: 45703 | CX11: Ivan | CY11: -60 | CZ11: Ivan | DA11: 45729 | DB11: Tour Sintra Where To #416 | DC11: 38.4 | DD11: Afonso/Renato | DO11: 46003 | DP11: Coop Táxis | DQ11: 32.8 | DR11: Erica | DX11: Comissão Discover | DY11: =SUM(Tours!Q30:Q50) -> 50.4
